Workbook

Sheet RAG Comparison
A1: question_type | B1: rag | C1: context_precision | D1: context_recall | E1: helpfulness | F1: answer_accuracy | G1: factual_correctness | H1: rouge_score(mode=precision) | I1: rouge_score(mode=recall) | J1: llm_calls | K1: total_cost | L1: total_tokens | M1: routing_cost | N1: routing_tokens | O1: generation_cost | P1: generation_tokens
A2: straightforward | B2: LLM Retriever | C2: 0.6329 | D2: 0.84 | E2: 4.44 | F2: 0.72 | G2: 0.44 | H2: 0.147 | I2: 0.4155 | J2: 3.56 | K2: 0.007947 | L2: 30420.48 | M2: 0.007421 | N2: 29045.96 | O2: 0.000527 | P2: 1374.52
A3: straightforward | B3: Naive RAG | C3: 0.6014 | D3: 0.88 | E3: 4.64 | F3: 0.8 | G3: 0.4436 | H3: 0.1307 | I3: 0.444 | J3: 1 | K3: 0.000747 | L3: 2243.88 | O3: 0.000747 | P3: 2243.88
A4: straightforward | B4: RAPTOR | C4: 0.6153 | D4: 0.86 | E4: 4.56 | F4: 0.81 | G4: 0.5276 | H4: 0.1309 | I4: 0.4389 | J4: 1 | K4: 0.000697 | L4: 2126.12 | O4: 0.000697 | P4: 2126.12
A5: multi_hop | B5: LLM Retriever | C5: 0.6864 | D5: 0.8773 | E5: 4.92 | F5: 0.94 | G5: 0.556 | H5: 0.1563 | I5: 0.3744 | J5: 3.92 | K5: 0.009349 | L5: 35315.28 | M5: 0.008355 | N5: 32800.6 | O5: 0.000994 | P5: 2514.68
A6: multi_hop | B6: Naive RAG | C6: 0.5034 | D6: 0.724 | E6: 5 | F6: 0.85 | G6: 0.4164 | H6: 0.1542 | I6: 0.3339 | J6: 1 | K6: 0.000885 | L6: 2297.32 | O6: 0.000885 | P6: 2297.32
A7: multi_hop | B7: RAPTOR | C7: 0.5891 | D7: 0.72 | E7: 4.68 | F7: 0.84 | G7: 0.4732 | H7: 0.1526 | I7: 0.3225 | J7: 1 | K7: 0.000898 | L7: 2391.68 | O7: 0.000898 | P7: 2391.68
A8: intent_driven | B8: LLM Retriever | C8: 0.817 | D8: 0.948 | E8: 5 | F8: 0.96 | G8: 0.56 | H8: 0.1455 | I8: 0.4583 | J8: 3.52 | K8: 0.008602 | L8: 32730.76 | M8: 0.007716 | N8: 30653.88 | O8: 0.000886 | P8: 2076.88
A9: intent_driven | B9: Naive RAG | C9: 0.592 | D9: 0.8233 | E9: 4.52 | F9: 0.81 | G9: 0.4568 | H9: 0.1468 | I9: 0.4019 | J9: 1 | K9: 0.000823 | L9: 2285.28 | O9: 0.000823 | P9: 2285.28
A10: intent_driven | B10: RAPTOR | C10: 0.6675 | D10: 0.8153 | E10: 4.56 | F10: 0.82 | G10: 0.4628 | H10: 0.1578 | I10: 0.408 | J10: 1 | K10: 0.000872 | L10: 2403.8 | O10: 0.000872 | P10: 2403.8
A11: debugging | B11: LLM Retriever | C11: 0.7658 | D11: 0.87 | E11: 4.8 | F11: 0.84 | G11: 0.5892 | H11: 0.1669 | I11: 0.4052 | J11: 3.72 | K11: 0.008984 | L11: 34701.68 | M11: 0.0083 | N11: 32825.96 | O11: 0.000684 | P11: 1875.72
A12: debugging | B12: Naive RAG | C12: 0.7195 | D12: 0.9633 | E12: 4.92 | F12: 0.94 | G12: 0.6868 | H12: 0.1922 | I12: 0.4088 | J12: 1 | K12: 0.000756 | L12: 2308.16 | O12: 0.000756 | P12: 2308.16
A13: debugging | B13: RAPTOR | C13: 0.7332 | D13: 0.9467 | E13: 4.88 | F13: 0.9 | G13: 0.5908 | H13: 0.1946 | I13: 0.4261 | J13: 1 | K13: 0.000791 | L13: 2378 | O13: 0.000791 | P13: 2378

Sheet Sheet1
A1: RAG Comparison by Question Type
A3: Context Precision (higher is better)
A4: Question Type | B4: LLM Retriever | C4: Naive RAG | D4: RAPTOR
A5: straightforward | B5: =SUMIFS('RAG Comparison'!$C$2:$C$13,'RAG Comparison'!$A$2:$A$13,$A5,'RAG Comparison'!$B$2:$B$13,B$4) -> 0.6329 | C5: =SUMIFS('RAG Comparison'!$C$2:$C$13,'RAG Comparison'!$A$2:$A$13,$A5,'RAG Comparison'!$B$2:$B$13,C$4) -> 0.6014 | D5: =SUMIFS('RAG Comparison'!$C$2:$C$13,'RAG Comparison'!$A$2:$A$13,$A5,'RAG Comparison'!$B$2:$B$13,D$4) -> 0.6153
A6: multi_hop | B6: =SUMIFS('RAG Comparison'!$C$2:$C$13,'RAG Comparison'!$A$2:$A$13,$A6,'RAG Comparison'!$B$2:$B$13,B$4) -> 0.6864 | C6: =SUMIFS('RAG Comparison'!$C$2:$C$13,'RAG Comparison'!$A$2:$A$13,$A6,'RAG Comparison'!$B$2:$B$13,C$4) -> 0.5034 | D6: =SUMIFS('RAG Comparison'!$C$2:$C$13,'RAG Comparison'!$A$2:$A$13,$A6,'RAG Comparison'!$B$2:$B$13,D$4) -> 0.5891
A7: intent_driven | B7: =SUMIFS('RAG Comparison'!$C$2:$C$13,'RAG Comparison'!$A$2:$A$13,$A7,'RAG Comparison'!$B$2:$B$13,B$4) -> 0.817 | C7: =SUMIFS('RAG Comparison'!$C$2:$C$13,'RAG Comparison'!$A$2:$A$13,$A7,'RAG Comparison'!$B$2:$B$13,C$4) -> 0.592 | D7: =SUMIFS('RAG Comparison'!$C$2:$C$13,'RAG Comparison'!$A$2:$A$13,$A7,'RAG Comparison'!$B$2:$B$13,D$4) -> 0.6675
A8: debugging | B8: =SUMIFS('RAG Comparison'!$C$2:$C$13,'RAG Comparison'!$A$2:$A$13,$A8,'RAG Comparison'!$B$2:$B$13,B$4) -> 0.7658 | C8: =SUMIFS('RAG Comparison'!$C$2:$C$13,'RAG Comparison'!$A$2:$A$13,$A8,'RAG Comparison'!$B$2:$B$13,C$4) -> 0.7195 | D8: =SUMIFS('RAG Comparison'!$C$2:$C$13,'RAG Comparison'!$A$2:$A$13,$A8,'RAG Comparison'!$B$2:$B$13,D$4) -> 0.7332
A11: Context Recall (higher is better)
A12: Question Type | B12: LLM Retriever | C12: Naive RAG | D12: RAPTOR
A13: straightforward | B13: =SUMIFS('RAG Comparison'!$D$2:$D$13,'RAG Comparison'!$A$2:$A$13,$A13,'RAG Comparison'!$B$2:$B$13,B$12) -> 0.84 | C13: =SUMIFS('RAG Comparison'!$D$2:$D$13,'RAG Comparison'!$A$2:$A$13,$A13,'RAG Comparison'!$B$2:$B$13,C$12) -> 0.88 | D13: =SUMIFS('RAG Comparison'!$D$2:$D$13,'RAG Comparison'!$A$2:$A$13,$A13,'RAG Comparison'!$B$2:$B$13,D$12) -> 0.86
A14: multi_hop | B14: =SUMIFS('RAG Comparison'!$D$2:$D$13,'RAG Comparison'!$A$2:$A$13,$A14,'RAG Comparison'!$B$2:$B$13,B$12) -> 0.8773 | C14: =SUMIFS('RAG Comparison'!$D$2:$D$13,'RAG Comparison'!$A$2:$A$13,$A14,'RAG Comparison'!$B$2:$B$13,C$12) -> 0.724 | D14: =SUMIFS('RAG Comparison'!$D$2:$D$13,'RAG Comparison'!$A$2:$A$13,$A14,'RAG Comparison'!$B$2:$B$13,D$12) -> 0.72
A15: intent_driven | B15: =SUMIFS('RAG Comparison'!$D$2:$D$13,'RAG Comparison'!$A$2:$A$13,$A15,'RAG Comparison'!$B$2:$B$13,B$12) -> 0.948 | C15: =SUMIFS('RAG Comparison'!$D$2:$D$13,'RAG Comparison'!$A$2:$A$13,$A15,'RAG Comparison'!$B$2:$B$13,C$12) -> 0.8233 | D15: =SUMIFS('RAG Comparison'!$D$2:$D$13,'RAG Comparison'!$A$2:$A$13,$A15,'RAG Comparison'!$B$2:$B$13,D$12) -> 0.8153
A16: debugging | B16: =SUMIFS('RAG Comparison'!$D$2:$D$13,'RAG Comparison'!$A$2:$A$13,$A16,'RAG Comparison'!$B$2:$B$13,B$12) -> 0.87 | C16: =SUMIFS('RAG Comparison'!$D$2:$D$13,'RAG Comparison'!$A$2:$A$13,$A16,'RAG Comparison'!$B$2:$B$13,C$12) -> 0.9633 | D16: =SUMIFS('RAG Comparison'!$D$2:$D$13,'RAG Comparison'!$A$2:$A$13,$A16,'RAG Comparison'!$B$2:$B$13,D$12) -> 0.9467
A19: Answer Accuracy (higher is better)
A20: Question Type | B20: LLM Retriever | C20: Naive RAG | D20: RAPTOR
A21: straightforward | B21: =SUMIFS('RAG Comparison'!$F$2:$F$13,'RAG Comparison'!$A$2:$A$13,$A21,'RAG Comparison'!$B$2:$B$13,B$20) -> 0.72 | C21: =SUMIFS('RAG Comparison'!$F$2:$F$13,'RAG Comparison'!$A$2:$A$13,$A21,'RAG Comparison'!$B$2:$B$13,C$20) -> 0.8 | D21: =SUMIFS('RAG Comparison'!$F$2:$F$13,'RAG Comparison'!$A$2:$A$13,$A21,'RAG Comparison'!$B$2:$B$13,D$20) -> 0.81
A22: multi_hop | B22: =SUMIFS('RAG Comparison'!$F$2:$F$13,'RAG Comparison'!$A$2:$A$13,$A22,'RAG Comparison'!$B$2:$B$13,B$20) -> 0.94 | C22: =SUMIFS('RAG Comparison'!$F$2:$F$13,'RAG Comparison'!$A$2:$A$13,$A22,'RAG Comparison'!$B$2:$B$13,C$20) -> 0.85 | D22: =SUMIFS('RAG Comparison'!$F$2:$F$13,'RAG Comparison'!$A$2:$A$13,$A22,'RAG Comparison'!$B$2:$B$13,D$20) -> 0.84
A23: intent_driven | B23: =SUMIFS('RAG Comparison'!$F$2:$F$13,'RAG Comparison'!$A$2:$A$13,$A23,'RAG Comparison'!$B$2:$B$13,B$20) -> 0.96 | C23: =SUMIFS('RAG Comparison'!$F$2:$F$13,'RAG Comparison'!$A$2:$A$13,$A23,'RAG Comparison'!$B$2:$B$13,C$20) -> 0.81 | D23: =SUMIFS('RAG Comparison'!$F$2:$F$13,'RAG Comparison'!$A$2:$A$13,$A23,'RAG Comparison'!$B$2:$B$13,D$20) -> 0.82
A24: debugging | B24: =SUMIFS('RAG Comparison'!$F$2:$F$13,'RAG Comparison'!$A$2:$A$13,$A24,'RAG Comparison'!$B$2:$B$13,B$20) -> 0.84 | C24: =SUMIFS('RAG Comparison'!$F$2:$F$13,'RAG Comparison'!$A$2:$A$13,$A24,'RAG Comparison'!$B$2:$B$13,C$20) -> 0.94 | D24: =SUMIFS('RAG Comparison'!$F$2:$F$13,'RAG Comparison'!$A$2:$A$13,$A24,'RAG Comparison'!$B$2:$B$13,D$20) -> 0.9
A27: Helpfulness (1-5) (higher is better)
A28: Question Type | B28: LLM Retriever | C28: Naive RAG | D28: RAPTOR
A29: straightforward | B29: =SUMIFS('RAG Comparison'!$E$2:$E$13,'RAG Comparison'!$A$2:$A$13,$A29,'RAG Comparison'!$B$2:$B$13,B$28) -> 4.44 | C29: =SUMIFS('RAG Comparison'!$E$2:$E$13,'RAG Comparison'!$A$2:$A$13,$A29,'RAG Comparison'!$B$2:$B$13,C$28) -> 4.64 | D29: =SUMIFS('RAG Comparison'!$E$2:$E$13,'RAG Comparison'!$A$2:$A$13,$A29,'RAG Comparison'!$B$2:$B$13,D$28) -> 4.56
A30: multi_hop | B30: =SUMIFS('RAG Comparison'!$E$2:$E$13,'RAG Comparison'!$A$2:$A$13,$A30,'RAG Comparison'!$B$2:$B$13,B$28) -> 4.92 | C30: =SUMIFS('RAG Comparison'!$E$2:$E$13,'RAG Comparison'!$A$2:$A$13,$A30,'RAG Comparison'!$B$2:$B$13,C$28) -> 5 | D30: =SUMIFS('RAG Comparison'!$E$2:$E$13,'RAG Comparison'!$A$2:$A$13,$A30,'RAG Comparison'!$B$2:$B$13,D$28) -> 4.68
A31: intent_driven | B31: =SUMIFS('RAG Comparison'!$E$2:$E$13,'RAG Comparison'!$A$2:$A$13,$A31,'RAG Comparison'!$B$2:$B$13,B$28) -> 5 | C31: =SUMIFS('RAG Comparison'!$E$2:$E$13,'RAG Comparison'!$A$2:$A$13,$A31,'RAG Comparison'!$B$2:$B$13,C$28) -> 4.52 | D31: =SUMIFS('RAG Comparison'!$E$2:$E$13,'RAG Comparison'!$A$2:$A$13,$A31,'RAG Comparison'!$B$2:$B$13,D$28) -> 4.56
A32: debugging | B32: =SUMIFS('RAG Comparison'!$E$2:$E$13,'RAG Comparison'!$A$2:$A$13,$A32,'RAG Comparison'!$B$2:$B$13,B$28) -> 4.8 | C32: =SUMIFS('RAG Comparison'!$E$2:$E$13,'RAG Comparison'!$A$2:$A$13,$A32,'RAG Comparison'!$B$2:$B$13,C$28) -> 4.92 | D32: =SUMIFS('RAG Comparison'!$E$2:$E$13,'RAG Comparison'!$A$2:$A$13,$A32,'RAG Comparison'!$B$2:$B$13,D$28) -> 4.88
A35: Factual Correctness (higher is better)
A36: Question Type | B36: LLM Retriever | C36: Naive RAG | D36: RAPTOR
A37: straightforward | B37: =SUMIFS('RAG Comparison'!$G$2:$G$13,'RAG Comparison'!$A$2:$A$13,$A37,'RAG Comparison'!$B$2:$B$13,B$36) -> 0.44 | C37: =SUMIFS('RAG Comparison'!$G$2:$G$13,'RAG Comparison'!$A$2:$A$13,$A37,'RAG Comparison'!$B$2:$B$13,C$36) -> 0.4436 | D37: =SUMIFS('RAG Comparison'!$G$2:$G$13,'RAG Comparison'!$A$2:$A$13,$A37,'RAG Comparison'!$B$2:$B$13,D$36) -> 0.5276
A38: multi_hop | B38: =SUMIFS('RAG Comparison'!$G$2:$G$13,'RAG Comparison'!$A$2:$A$13,$A38,'RAG Comparison'!$B$2:$B$13,B$36) -> 0.556 | C38: =SUMIFS('RAG Comparison'!$G$2:$G$13,'RAG Comparison'!$A$2:$A$13,$A38,'RAG Comparison'!$B$2:$B$13,C$36) -> 0.4164 | D38: =SUMIFS('RAG Comparison'!$G$2:$G$13,'RAG Comparison'!$A$2:$A$13,$A38,'RAG Comparison'!$B$2:$B$13,D$36) -> 0.4732
A39: intent_driven | B39: =SUMIFS('RAG Comparison'!$G$2:$G$13,'RAG Comparison'!$A$2:$A$13,$A39,'RAG Comparison'!$B$2:$B$13,B$36) -> 0.56 | C39: =SUMIFS('RAG Comparison'!$G$2:$G$13,'RAG Comparison'!$A$2:$A$13,$A39,'RAG Comparison'!$B$2:$B$13,C$36) -> 0.4568 | D39: =SUMIFS('RAG Comparison'!$G$2:$G$13,'RAG Comparison'!$A$2:$A$13,$A39,'RAG Comparison'!$B$2:$B$13,D$36) -> 0.4628
A40: debugging | B40: =SUMIFS('RAG Comparison'!$G$2:$G$13,'RAG Comparison'!$A$2:$A$13,$A40,'RAG Comparison'!$B$2:$B$13,B$36) -> 0.5892 | C40: =SUMIFS('RAG Comparison'!$G$2:$G$13,'RAG Comparison'!$A$2:$A$13,$A40,'RAG Comparison'!$B$2:$B$13,C$36) -> 0.6868 | D40: =SUMIFS('RAG Comparison'!$G$2:$G$13,'RAG Comparison'!$A$2:$A$13,$A40,'RAG Comparison'!$B$2:$B$13,D$36) -> 0.5908
A43: Total Cost ($ per query) (lower is better)
A44: Question Type | B44: LLM Retriever | C44: Naive RAG | D44: RAPTOR
A45: straightforward | B45: =SUMIFS('RAG Comparison'!$K$2:$K$13,'RAG Comparison'!$A$2:$A$13,$A45,'RAG Comparison'!$B$2:$B$13,B$44) -> 0.007947 | C45: =SUMIFS('RAG Comparison'!$K$2:$K$13,'RAG Comparison'!$A$2:$A$13,$A45,'RAG Comparison'!$B$2:$B$13,C$44) -> 0.000747 | D45: =SUMIFS('RAG Comparison'!$K$2:$K$13,'RAG Comparison'!$A$2:$A$13,$A45,'RAG Comparison'!$B$2:$B$13,D$44) -> 0.000697
A46: multi_hop | B46: =SUMIFS('RAG Comparison'!$K$2:$K$13,'RAG Comparison'!$A$2:$A$13,$A46,'RAG Comparison'!$B$2:$B$13,B$44) -> 0.009349 | C46: =SUMIFS('RAG Comparison'!$K$2:$K$13,'RAG Comparison'!$A$2:$A$13,$A46,'RAG Comparison'!$B$2:$B$13,C$44) -> 0.000885 | D46: =SUMIFS('RAG Comparison'!$K$2:$K$13,'RAG Comparison'!$A$2:$A$13,$A46,'RAG Comparison'!$B$2:$B$13,D$44) -> 0.000898
A47: intent_driven | B47: =SUMIFS('RAG Comparison'!$K$2:$K$13,'RAG Comparison'!$A$2:$A$13,$A47,'RAG Comparison'!$B$2:$B$13,B$44) -> 0.008602 | C47: =SUMIFS('RAG Comparison'!$K$2:$K$13,'RAG Comparison'!$A$2:$A$13,$A47,'RAG Comparison'!$B$2:$B$13,C$44) -> 0.000823 | D47: =SUMIFS('RAG Comparison'!$K$2:$K$13,'RAG Comparison'!$A$2:$A$13,$A47,'RAG Comparison'!$B$2:$B$13,D$44) -> 0.000872
A48: debugging | B48: =SUMIFS('RAG Comparison'!$K$2:$K$13,'RAG Comparison'!$A$2:$A$13,$A48,'RAG Comparison'!$B$2:$B$13,B$44) -> 0.008984 | C48: =SUMIFS('RAG Comparison'!$K$2:$K$13,'RAG Comparison'!$A$2:$A$13,$A48,'RAG Comparison'!$B$2:$B$13,C$44) -> 0.000756 | D48: =SUMIFS('RAG Comparison'!$K$2:$K$13,'RAG Comparison'!$A$2:$A$13,$A48,'RAG Comparison'!$B$2:$B$13,D$44) -> 0.000791
A51: Generation Cost ($ per query) (lower is better)
A52: Question Type | B52: LLM Retriever | C52: Naive RAG | D52: RAPTOR
A53: straightforward | B53: =SUMIFS('RAG Comparison'!$O$2:$O$13,'RAG Comparison'!$A$2:$A$13,$A53,'RAG Comparison'!$B$2:$B$13,B$52) -> 0.000527 | C53: =SUMIFS('RAG Comparison'!$O$2:$O$13,'RAG Comparison'!$A$2:$A$13,$A53,'RAG Comparison'!$B$2:$B$13,C$52) -> 0.000747 | D53: =SUMIFS('RAG Comparison'!$O$2:$O$13,'RAG Comparison'!$A$2:$A$13,$A53,'RAG Comparison'!$B$2:$B$13,D$52) -> 0.000697
...
